<?xml version='1.0' encoding='UTF-8'?>
<robot xmlns:xacro="http://www.ros.org/wiki/xacro" name="AR5-5_07R-W4C4A2">
  <!-- Constants for robot dimensions -->
  <material name="black">
    <color rgba="0.0 0.0 0.0 1.0"/>
  </material>
  <material name="blue">
    <color rgba="0.0 0.0 0.8 1.0"/>
  </material>
  <material name="green">
    <color rgba="0.0 0.8 0.0 1.0"/>
  </material>
  <material name="grey">
    <color rgba="0.2 0.2 0.2 1.0"/>
  </material>
  <material name="orange">
    <color rgba="1.0 0.423529411765 0.0392156862745 1.0"/>
  </material>
  <material name="brown">
    <color rgba="0.870588235294 0.811764705882 0.764705882353 1.0"/>
  </material>
  <material name="red">
    <color rgba="0.8 0.0 0.0 1.0"/>
  </material>
  <material name="white">
    <color rgba="1.0 1.0 1.0 1.0"/>
  </material>
  <material name="Beige">
    <color rgba="1.0 0.784 0.5765 1.0"/>
  </material>
  <!-- Used for fixing robot to Gazebo 'base_link' -->
  <link name="world"/>
  <joint name="fixed" type="fixed">
    <parent link="world"/>
    <child link="AR5-5_07R-W4C4A2_base"/>
  </joint>
  <!--base-->
  <link name="AR5-5_07R-W4C4A2_base">
    <visual>
      <geometry>
        <mesh filename="package://AR5-5_07R-W4C4A2_description/meshes/AR5-5_07R-W4C4A2_base.stl" scale="0.001 0.001 0.001"/>
      </geometry>
      <origin rpy="0 0 0" xyz="0.0 0.0 0.0"/>
      <material name="white"/>
    </visual>
    <collision>
      <geometry>
        <mesh filename="package://AR5-5_07R-W4C4A2_description/meshes/AR5-5_07R-W4C4A2_base.stl" scale="0.001 0.001 0.001"/>
      </geometry>
      <origin rpy="0 0 0" xyz="0.0 0.0 0.0"/>
    </collision>
  </link>
  <joint name="AR5-5_07R-W4C4A2_joint_1" type="revolute">
    <parent link="AR5-5_07R-W4C4A2_base"/>
    <child link="AR5-5_07R-W4C4A2_link1"/>
    <limit effort="108" lower="-3.1067" upper="3.1067" velocity="3.0543261909900763"/>
    <axis xyz="0 0 1"/>
    <origin rpy="0 0 0" xyz="0.0 0.0 0.0"/>
    <dynamics damping="2.7440893120e-01" friction="2.9299581704e-01"/>
  </joint>
  <transmission name="tran1">
    <type>transmission_interface/SimpleTransmission</type>
    <joint name="AR5-5_07R-W4C4A2_joint_8">
      <hardwareInterface>EffortJointInterface</hardwareInterface>
    </joint>
    <actuator name="motor1">
      <hardwareInterface>EffortJointInterface</hardwareInterface>
      <mechanicalReduction>1</mechanicalReduction>
    </actuator>
  </transmission>
  <!--link 1-->
  <link name="AR5-5_07R-W4C4A2_link1">
    <visual>
      <geometry>
        <mesh filename="package://AR5-5_07R-W4C4A2_description/meshes/AR5-5_07R-W4C4A2_link1.stl" scale="0.001 0.001 0.001"/>
      </geometry>
      <origin rpy="0 0 0" xyz="0 0 0"/>
      <material name="white"/>
    </visual>
    <inertial>
    <mass value="2.692410" />
    <inertia ixx="6.309174e-02" ixy="3.847911e-06" ixz="2.733635e-05" iyy="6.255405e-02" iyz="-4.649738e-06" izz="1.022790e-05" />
    <origin rpy="0 0 0" xyz="0.006762 0.000129 0.080596" />
    </inertial>
    <collision>
      <geometry>
        <mesh filename="package://AR5-5_07R-W4C4A2_description/meshes/AR5-5_07R-W4C4A2_link1.stl" scale="0.001 0.001 0.001"/>
      </geometry>
      <origin rpy="0 0 0" xyz="0 0 0"/>
    </collision>
  </link>
  <joint name="AR5-5_07R-W4C4A2_joint_2" type="revolute">
    <parent link="AR5-5_07R-W4C4A2_link1"/>
    <child link="AR5-5_07R-W4C4A2_link2"/>
    <limit effort="108" lower="-2.0944" upper="2.0944" velocity="3.0543261909900763"/>
    <axis xyz="0 1 0"/>
    <origin rpy="0 0 0" xyz="0.0 0.0 0.174522"/>
    <dynamics damping="-2.7661315154e-01" friction="2.8966689341e-01"/>
  </joint>
  <transmission name="tran2">
    <type>transmission_interface/SimpleTransmission</type>
    <joint name="xmate_joint_2">
      <hardwareInterface>EffortJointInterface</hardwareInterface>
    </joint>
    <actuator name="motor2">
      <hardwareInterface>EffortJointInterface</hardwareInterface>
      <mechanicalReduction>1</mechanicalReduction>
    </actuator>
  </transmission>
  <!--link 2-->
  <link name="AR5-5_07R-W4C4A2_link2">
    <visual>
      <geometry>
        <mesh filename="package://AR5-5_07R-W4C4A2_description/meshes/AR5-5_07R-W4C4A2_link2.stl" scale="0.001 0.001 0.001"/>
      </geometry>
      <origin rpy="0 0 0" xyz="0 0 0.0"/>
      <material name="white"/>
    </visual>
    <inertial>
    <mass value="2.353383" />
    <inertia ixx="1.811788e-06" ixy="1.061974e-07" ixz="-6.874123e-08" iyy="-3.124813e-06" iyz="4.477312e-08" izz="1.969154e-06" />
    <origin rpy="0 0 0" xyz="-0.013424 -0.001240 0.299711" />
    </inertial>
    <collision>
      <geometry>
        <mesh filename="package://AR5-5_07R-W4C4A2_description/meshes/AR5-5_07R-W4C4A2_link2.stl" scale="0.001 0.001 0.001"/>
      </geometry>
      <origin rpy="0 0 0" xyz="0 0 0.0"/>
    </collision>
  </link>
  <joint name="AR5-5_07R-W4C4A2_joint_3" type="revolute">
    <parent link="AR5-5_07R-W4C4A2_link2"/>
    <child link="AR5-5_07R-W4C4A2_link3"/>
    <limit effort="66" lower="-3.1067" upper="3.1067" velocity="4.71238898038469"/>
    <axis xyz="0 0 1"/>
    <origin rpy="0 0 0" xyz="0.0 0.0 0.314726"/>
    <dynamics damping="-1.4499125401e-02" friction="2.8692269342e-01"/>
  </joint>
  <transmission name="tran3">
    <type>transmission_interface/SimpleTransmission</type>
    <joint name="xmate_joint_3">
      <hardwareInterface>EffortJointInterface</hardwareInterface>
    </joint>
    <actuator name="motor3">
      <hardwareInterface>EffortJointInterface</hardwareInterface>
      <mechanicalReduction>1</mechanicalReduction>
    </actuator>
  </transmission>
  <!--link 3-->
  <link name="AR5-5_07R-W4C4A2_link3">
    <visual>
      <geometry>
        <mesh filename="package://AR5-5_07R-W4C4A2_description/meshes/AR5-5_07R-W4C4A2_link3.stl" scale="0.001 0.001 0.001"/>
      </geometry>
      <origin rpy="0 0 0" xyz="0 0 0"/>
      <material name="white"/>
    </visual>
    <inertial>
    <mass value="1.899195" />
    <inertia ixx="-5.486408e-07" ixy="-7.980053e-08" ixz="1.591479e-07" iyy="6.942296e-07" iyz="-6.712456e-09" izz="1.821610e-06" />
    <origin rpy="0 0 0" xyz="0.008052 0.000692 -0.174099" />
    </inertial>
    <collision>
      <geometry>
        <mesh filename="package://AR5-5_07R-W4C4A2_description/meshes/AR5-5_07R-W4C4A2_link3.stl" scale="0.001 0.001 0.001"/>
      </geometry>
      <origin rpy="0 0 0" xyz="0 0 0"/>
    </collision>
  </link>
  <joint name="AR5-5_07R-W4C4A2_joint_4" type="revolute">
    <parent link="AR5-5_07R-W4C4A2_link3"/>
    <child link="AR5-5_07R-W4C4A2_link4"/>
    <limit effort="66" lower="-1.0472" upper="2.5307" velocity="5.235987755982989"/>
    <!--     lower="-1.0472" upper="1.0472" -->
    <axis xyz="0 1 0"/>
    <!--     <origin rpy="0 0 0" xyz=0.01 0.0 0.0/> -->
    <origin rpy="0 0 0" xyz="0.01 0.0 0.0"/>
    <dynamics damping="-5.3508692759e-01" friction="4.9841900205e-01"/>
  </joint>
  <transmission name="tran4">
    <type>transmission_interface/SimpleTransmission</type>
    <joint name="xmate_joint_4">
      <hardwareInterface>EffortJointInterface</hardwareInterface>
    </joint>
    <actuator name="motor4">
      <hardwareInterface>EffortJointInterface</hardwareInterface>
      <mechanicalReduction>1</mechanicalReduction>
    </actuator>
  </transmission>
  <!--link 4-->
  <link name="AR5-5_07R-W4C4A2_link4">
    <visual>
      <geometry>
        <mesh filename="package://AR5-5_07R-W4C4A2_description/meshes/AR5-5_07R-W4C4A2_link4.stl" scale=".001 0.001 0.001"/>
      </geometry>
      <origin rpy="0 0 0" xyz="0.0 0.0 0.0"/>
      <material name="white"/>
    </visual>
    <inertial>
    <mass value="1.283151" />
    <inertia ixx="2.906412e-07" ixy="-6.317760e-08" ixz="8.150149e-08" iyy="5.454186e-07" iyz="-1.158971e-08" izz="1.288848e-06" />
    <origin rpy="0 0 0" xyz="-0.003013 0.006686 0.217519" />
    </inertial>
    <collision>
      <geometry>
        <mesh filename="package://AR5-5_07R-W4C4A2_description/meshes/AR5-5_07R-W4C4A2_link4.stl" scale="0.001 0.001 0.001"/>
      </geometry>
      <origin rpy="0 0 0" xyz="0.0 0.0 0.0"/>
    </collision>
  </link>
  <joint name="AR5-5_07R-W4C4A2_joint_5" type="revolute">
    <parent link="AR5-5_07R-W4C4A2_link4"/>
    <child link="AR5-5_07R-W4C4A2_link5"/>
    <limit effort="19" lower="-3.1067" upper="3.1067" velocity="4.1887902047863905"/>
    <axis xyz="0 0 1"/>
    <origin rpy="0 0 0" xyz="-0.01 0.0 0.272656"/>
    <dynamics damping="1.4161280405e-02" friction="1.5474527341e-01"/>
  </joint>
  <transmission name="tran5">
    <type>transmission_interface/SimpleTransmission</type>
    <joint name="xmate_joint_5">
      <hardwareInterface>EffortJointInterface</hardwareInterface>
    </joint>
    <actuator name="motor5">
      <hardwareInterface>EffortJointInterface</hardwareInterface>
      <mechanicalReduction>1</mechanicalReduction>
    </actuator>
  </transmission>
  <!--link 5-->
  <link name="AR5-5_07R-W4C4A2_link5">
    <visual>
      <geometry>
        <mesh filename="package://AR5-5_07R-W4C4A2_description/meshes/AR5-5_07R-W4C4A2_link5.stl" scale="0.001 0.001 0.001"/>
      </geometry>
      <origin rpy="0 0 0" xyz="0 0 0"/>
      <material name="white"/>
    </visual>
    <inertial>
    <mass value="1.263756" />
    <inertia ixx="4.266931e-07" ixy="4.094769e-08" ixz="1.550278e-06" iyy="8.568301e-07" iyz="-9.357392e-07" izz="-1.932837e-06" />
    <origin rpy="0 0 0" xyz="0.000284 -0.001271 -0.142407" />
    </inertial>
    <collision>
      <geometry>
        <mesh filename="package://AR5-5_07R-W4C4A2_description/meshes/AR5-5_07R-W4C4A2_link5.stl" scale="0.001 0.001 0.001"/>
      </geometry>
      <origin rpy="0 0 0" xyz="0 0 0"/>
    </collision>
  </link>
  <joint name="AR5-5_07R-W4C4A2_joint_6" type="revolute">
    <parent link="AR5-5_07R-W4C4A2_link5"/>
    <child link="AR5-5_07R-W4C4A2_link6"/>
    <limit effort="19" lower="-1.0472" upper="1.0472" velocity="4.1887902047863905"/>
    <axis xyz="0 1 0"/>
    <origin rpy="0.0 0.0 0" xyz="0.0 0.0 0.0"/>
    <dynamics damping="-2.4630675741e-02" friction="4.4023599993e-01"/>
  </joint>
  <transmission name="tran6">
    <type>transmission_interface/SimpleTransmission</type>
    <joint name="xmate_joint_6">
      <hardwareInterface>EffortJointInterface</hardwareInterface>
    </joint>
    <actuator name="motor6">
      <hardwareInterface>EffortJointInterface</hardwareInterface>
      <mechanicalReduction>1</mechanicalReduction>
    </actuator>
  </transmission>
  <!--link 6-->
  <link name="AR5-5_07R-W4C4A2_link6">
    <visual>
      <geometry>
        <mesh filename="package://AR5-5_07R-W4C4A2_description/meshes/AR5-5_07R-W4C4A2_link6.stl" scale="0.001 0.001 0.001"/>
      </geometry>
      <origin rpy="0 0 0" xyz="0 0 0"/>
      <material name="white"/>
    </visual>
    <inertial>
    <mass value="0.706306" />
    <inertia ixx="1.106997e-06" ixy="1.172420e-06" ixz="1.612344e-06" iyy="8.060725e-06" iyz="-1.552402e-06" izz="-4.054969e-07" />
    <origin rpy="0 0 0" xyz="0.005100 -0.002406 -0.013071" />
    </inertial>
    <collision>
      <geometry>
        <mesh filename="package://AR5-5_07R-W4C4A2_description/meshes/AR5-5_07R-W4C4A2_link6.stl" scale="0.001 0.001 0.001"/>
      </geometry>
      <origin rpy="0 0 0" xyz="0 0 0"/>
    </collision>
  </link>
  <joint name="AR5-5_07R-W4C4A2_joint_7" type="revolute">
    <parent link="AR5-5_07R-W4C4A2_link6"/>
    <child link="AR5-5_07R-W4C4A2_link7"/>
    <limit effort="19" lower="-1.0472" upper="1.0472" velocity="4.1887902047863905"/>
    <axis xyz="1 0 0"/>
    <origin rpy="0.0 0.0 0" xyz="0.0 0.0 0.0"/>
    <dynamics damping="4.3316456486e-02" friction="1.0125261785e-01"/>
  </joint>
  <transmission name="tran7">
    <type>transmission_interface/SimpleTransmission</type>
    <joint name="xmate_joint_7">
      <hardwareInterface>EffortJointInterface</hardwareInterface>
    </joint>
    <actuator name="motor7">
      <hardwareInterface>EffortJointInterface</hardwareInterface>
      <mechanicalReduction>1</mechanicalReduction>
    </actuator>
  </transmission>
  <!--link 7-->
  <link name="AR5-5_07R-W4C4A2_link7">
    <visual>
      <geometry>
        <mesh filename="package://AR5-5_07R-W4C4A2_description/meshes/AR5-5_07R-W4C4A2_link7.stl" scale="0.001 0.001 0.001"/>
      </geometry>
      <origin rpy="0 0 0" xyz="0.0 0.0 0.0"/>
      <material name="white"/>
    </visual>
    <inertial>
    <mass value="0.111577" />
    <inertia ixx="-6.136220e-06" ixy="-5.294680e-07" ixz="4.028328e-06" iyy="6.041956e-06" iyz="-8.609296e-07" izz="3.083712e-07" />
    <origin rpy="0 0 0" xyz="0.006145 -0.025874 0.020462" />
    </inertial>
    <collision>
      <geometry>
        <mesh filename="package://AR5-5_07R-W4C4A2_description/meshes/AR5-5_07R-W4C4A2_link7.stl" scale="0.001 0.001 0.001"/>
      </geometry>
      <origin rpy="0 0 0" xyz="0.0 0.0 0.0"/>
    </collision>
  </link>
  <link name="AR5-5_07R-W4C4A2_tcp">
    <inertial>
      <mass value="0.0"/>
      <inertia ixx="1e-6" ixy="0" ixz="0" iyy="1e-6" iyz="0" izz="1e-6"/>
    </inertial>
  </link>
  <joint name="AR5-5_07R-W4C4A2_tcp_joint" type="fixed">
    <parent link="AR5-5_07R-W4C4A2_link7"/>
    <child link="AR5-5_07R-W4C4A2_tcp"/>
    <origin rpy="0 0 0" xyz="0.0 0.0 0.0968883"/>
  </joint>
</robot>
