<?xml version='1.0' encoding='UTF-8'?>
<robot xmlns:xacro="http://www.ros.org/wiki/xacro" name="AR5-5_07R-W4C4A2">
  <!-- Constants for robot dimensions -->
  <material name="black">
    <color rgba="0.0 0.0 0.0 1.0"/>
  </material>
  <material name="blue">
    <color rgba="0.0 0.0 0.8 1.0"/>
  </material>
  <material name="green">
    <color rgba="0.0 0.8 0.0 1.0"/>
  </material>
  <material name="grey">
    <color rgba="0.2 0.2 0.2 1.0"/>
  </material>
  <material name="orange">
    <color rgba="1.0 0.423529411765 0.0392156862745 1.0"/>
  </material>
  <material name="brown">
    <color rgba="0.870588235294 0.811764705882 0.764705882353 1.0"/>
  </material>
  <material name="red">
    <color rgba="0.8 0.0 0.0 1.0"/>
  </material>
  <material name="white">
    <color rgba="1.0 1.0 1.0 1.0"/>
  </material>
  <material name="Beige">
    <color rgba="1.0 0.784 0.5765 1.0"/>
  </material>
  <!-- Used for fixing robot to Gazebo 'base_link' -->
  <link name="world"/>
  <joint name="fixed" type="fixed">
    <parent link="world"/>
    <child link="AR5-5_07R-W4C4A2_base"/>
  </joint>
  <!--base-->
  <link name="AR5-5_07R-W4C4A2_base">
    <visual>
      <geometry>
        <mesh filename="package://AR5-5_07R-W4C4A2_description/meshes/AR5-5_07R-W4C4A2_base.stl" scale="0.001 0.001 0.001"/>
      </geometry>
      <origin rpy="0 0 0" xyz="0.0 0.0 0.0"/>
      <material name="white"/>
    </visual>
    <collision>
      <geometry>
        <mesh filename="package://AR5-5_07R-W4C4A2_description/meshes/AR5-5_07R-W4C4A2_base.stl" scale="0.001 0.001 0.001"/>
      </geometry>
      <origin rpy="0 0 0" xyz="0.0 0.0 0.0"/>
    </collision>
  </link>
  <joint name="AR5-5_07R-W4C4A2_joint_1" type="revolute">
    <parent link="AR5-5_07R-W4C4A2_base"/>
    <child link="AR5-5_07R-W4C4A2_link1"/>
    <limit effort="108" lower="-3.1067" upper="3.1067" velocity="3.0543261909900763"/>
    <axis xyz="0 0 1"/>
    <origin rpy="0 0 0" xyz="0.0 0.0 0.0"/>
    <dynamics damping="2.4764322616e-01" friction="2.9096271715e-01"/>
  </joint>
  <transmission name="tran1">
    <type>transmission_interface/SimpleTransmission</type>
    <joint name="AR5-5_07R-W4C4A2_joint_8">
      <hardwareInterface>EffortJointInterface</hardwareInterface>
    </joint>
    <actuator name="motor1">
      <hardwareInterface>EffortJointInterface</hardwareInterface>
      <mechanicalReduction>1</mechanicalReduction>
    </actuator>
  </transmission>
  <!--link 1-->
  <link name="AR5-5_07R-W4C4A2_link1">
    <visual>
      <geometry>
        <mesh filename="package://AR5-5_07R-W4C4A2_description/meshes/AR5-5_07R-W4C4A2_link1.stl" scale="0.001 0.001 0.001"/>
      </geometry>
      <origin rpy="0 0 0" xyz="0 0 0"/>
      <material name="white"/>
    </visual>
    <inertial>
    <mass value="2.683000" />
    <inertia ixx="4.936730e-03" ixy="1.600000e-06" ixz="-1.980000e-06" iyy="4.523440e-03" iyz="2.000000e-07" izz="4.329100e-03" />
    <origin rpy="0 0 0" xyz="-0.000001 0.000621 0.167909" />
    </inertial>
    <collision>
      <geometry>
        <mesh filename="package://AR5-5_07R-W4C4A2_description/meshes/AR5-5_07R-W4C4A2_link1.stl" scale="0.001 0.001 0.001"/>
      </geometry>
      <origin rpy="0 0 0" xyz="0 0 0"/>
    </collision>
  </link>
  <joint name="AR5-5_07R-W4C4A2_joint_2" type="revolute">
    <parent link="AR5-5_07R-W4C4A2_link1"/>
    <child link="AR5-5_07R-W4C4A2_link2"/>
    <limit effort="108" lower="-2.0944" upper="2.0944" velocity="3.0543261909900763"/>
    <axis xyz="0 1 0"/>
    <origin rpy="0 0 0" xyz="0.0 0.0 0.174522"/>
    <dynamics damping="-2.4116373742e-09" friction="2.1387516645e-01"/>
  </joint>
  <transmission name="tran2">
    <type>transmission_interface/SimpleTransmission</type>
    <joint name="xmate_joint_2">
      <hardwareInterface>EffortJointInterface</hardwareInterface>
    </joint>
    <actuator name="motor2">
      <hardwareInterface>EffortJointInterface</hardwareInterface>
      <mechanicalReduction>1</mechanicalReduction>
    </actuator>
  </transmission>
  <!--link 2-->
  <link name="AR5-5_07R-W4C4A2_link2">
    <visual>
      <geometry>
        <mesh filename="package://AR5-5_07R-W4C4A2_description/meshes/AR5-5_07R-W4C4A2_link2.stl" scale="0.001 0.001 0.001"/>
      </geometry>
      <origin rpy="0 0 0" xyz="0 0 0.0"/>
      <material name="white"/>
    </visual>
    <inertial>
    <mass value="2.300000" />
    <inertia ixx="1.151906e-02" ixy="2.460000e-06" ixz="5.500000e-07" iyy="9.933350e-03" iyz="-8.247700e-04" izz="4.352370e-03" />
    <origin rpy="0 0 0" xyz="0.000020 0.003081 0.102986" />
    </inertial>
    <collision>
      <geometry>
        <mesh filename="package://AR5-5_07R-W4C4A2_description/meshes/AR5-5_07R-W4C4A2_link2.stl" scale="0.001 0.001 0.001"/>
      </geometry>
      <origin rpy="0 0 0" xyz="0 0 0.0"/>
    </collision>
  </link>
  <joint name="AR5-5_07R-W4C4A2_joint_3" type="revolute">
    <parent link="AR5-5_07R-W4C4A2_link2"/>
    <child link="AR5-5_07R-W4C4A2_link3"/>
    <limit effort="66" lower="-3.1067" upper="3.1067" velocity="4.71238898038469"/>
    <axis xyz="0 0 1"/>
    <origin rpy="0 0 0" xyz="0.0 0.0 0.314726"/>
    <dynamics damping="1.6784797796e-02" friction="2.7017576454e-01"/>
  </joint>
  <transmission name="tran3">
    <type>transmission_interface/SimpleTransmission</type>
    <joint name="xmate_joint_3">
      <hardwareInterface>EffortJointInterface</hardwareInterface>
    </joint>
    <actuator name="motor3">
      <hardwareInterface>EffortJointInterface</hardwareInterface>
      <mechanicalReduction>1</mechanicalReduction>
    </actuator>
  </transmission>
  <!--link 3-->
  <link name="AR5-5_07R-W4C4A2_link3">
    <visual>
      <geometry>
        <mesh filename="package://AR5-5_07R-W4C4A2_description/meshes/AR5-5_07R-W4C4A2_link3.stl" scale="0.001 0.001 0.001"/>
      </geometry>
      <origin rpy="0 0 0" xyz="0 0 0"/>
      <material name="white"/>
    </visual>
    <inertial>
    <mass value="2.042885" />
    <inertia ixx="5.241202e-03" ixy="-1.346553e-05" ixz="3.760508e-04" iyy="4.757027e-03" iyz="-3.150667e-05" izz="2.676036e-03" />
    <origin rpy="0 0 0" xyz="0.006461 0.000597 -0.015052" />
    </inertial>
    <collision>
      <geometry>
        <mesh filename="package://AR5-5_07R-W4C4A2_description/meshes/AR5-5_07R-W4C4A2_link3.stl" scale="0.001 0.001 0.001"/>
      </geometry>
      <origin rpy="0 0 0" xyz="0 0 0"/>
    </collision>
  </link>
  <joint name="AR5-5_07R-W4C4A2_joint_4" type="revolute">
    <parent link="AR5-5_07R-W4C4A2_link3"/>
    <child link="AR5-5_07R-W4C4A2_link4"/>
    <limit effort="66" lower="-1.0472" upper="2.5307" velocity="5.235987755982989"/>
    <!--     lower="-1.0472" upper="1.0472" -->
    <axis xyz="0 1 0"/>
    <!--     <origin rpy="0 0 0" xyz=0.01 0.0 0.0/> -->
    <origin rpy="0 0 0" xyz="0.01 0.0 0.0"/>
    <dynamics damping="-4.3565432799e-09" friction="3.3444168179e-01"/>
  </joint>
  <transmission name="tran4">
    <type>transmission_interface/SimpleTransmission</type>
    <joint name="xmate_joint_4">
      <hardwareInterface>EffortJointInterface</hardwareInterface>
    </joint>
    <actuator name="motor4">
      <hardwareInterface>EffortJointInterface</hardwareInterface>
      <mechanicalReduction>1</mechanicalReduction>
    </actuator>
  </transmission>
  <!--link 4-->
  <link name="AR5-5_07R-W4C4A2_link4">
    <visual>
      <geometry>
        <mesh filename="package://AR5-5_07R-W4C4A2_description/meshes/AR5-5_07R-W4C4A2_link4.stl" scale=".001 0.001 0.001"/>
      </geometry>
      <origin rpy="0 0 0" xyz="0.0 0.0 0.0"/>
      <material name="white"/>
    </visual>
    <inertial>
    <mass value="1.575147" />
    <inertia ixx="5.340626e-03" ixy="5.556022e-05" ixz="-1.590595e-05" iyy="4.543236e-03" iyz="-5.491599e-04" izz="1.904909e-03" />
    <origin rpy="0 0 0" xyz="-0.006136 0.003297 0.057505" />
    </inertial>
    <collision>
      <geometry>
        <mesh filename="package://AR5-5_07R-W4C4A2_description/meshes/AR5-5_07R-W4C4A2_link4.stl" scale="0.001 0.001 0.001"/>
      </geometry>
      <origin rpy="0 0 0" xyz="0.0 0.0 0.0"/>
    </collision>
  </link>
  <joint name="AR5-5_07R-W4C4A2_joint_5" type="revolute">
    <parent link="AR5-5_07R-W4C4A2_link4"/>
    <child link="AR5-5_07R-W4C4A2_link5"/>
    <limit effort="19" lower="-3.1067" upper="3.1067" velocity="4.1887902047863905"/>
    <axis xyz="0 0 1"/>
    <origin rpy="0 0 0" xyz="-0.01 0.0 0.272656"/>
    <dynamics damping="1.8881323670e-03" friction="1.5478641888e-01"/>
  </joint>
  <transmission name="tran5">
    <type>transmission_interface/SimpleTransmission</type>
    <joint name="xmate_joint_5">
      <hardwareInterface>EffortJointInterface</hardwareInterface>
    </joint>
    <actuator name="motor5">
      <hardwareInterface>EffortJointInterface</hardwareInterface>
      <mechanicalReduction>1</mechanicalReduction>
    </actuator>
  </transmission>
  <!--link 5-->
  <link name="AR5-5_07R-W4C4A2_link5">
    <visual>
      <geometry>
        <mesh filename="package://AR5-5_07R-W4C4A2_description/meshes/AR5-5_07R-W4C4A2_link5.stl" scale="0.001 0.001 0.001"/>
      </geometry>
      <origin rpy="0 0 0" xyz="0 0 0"/>
      <material name="white"/>
    </visual>
    <inertial>
    <mass value="1.226457" />
    <inertia ixx="2.064246e-03" ixy="-1.280346e-05" ixz="1.701058e-05" iyy="1.431887e-03" iyz="-7.693932e-06" izz="1.850953e-03" />
    <origin rpy="0 0 0" xyz="0.000290 -0.001597 -0.091110" />
    </inertial>
    <collision>
      <geometry>
        <mesh filename="package://AR5-5_07R-W4C4A2_description/meshes/AR5-5_07R-W4C4A2_link5.stl" scale="0.001 0.001 0.001"/>
      </geometry>
      <origin rpy="0 0 0" xyz="0 0 0"/>
    </collision>
  </link>
  <joint name="AR5-5_07R-W4C4A2_joint_6" type="revolute">
    <parent link="AR5-5_07R-W4C4A2_link5"/>
    <child link="AR5-5_07R-W4C4A2_link6"/>
    <limit effort="19" lower="-1.0472" upper="1.0472" velocity="4.1887902047863905"/>
    <axis xyz="0 1 0"/>
    <origin rpy="0.0 0.0 0" xyz="0.0 0.0 0.0"/>
    <dynamics damping="-2.7280494969e-10" friction="4.3107949252e-01"/>
  </joint>
  <transmission name="tran6">
    <type>transmission_interface/SimpleTransmission</type>
    <joint name="xmate_joint_6">
      <hardwareInterface>EffortJointInterface</hardwareInterface>
    </joint>
    <actuator name="motor6">
      <hardwareInterface>EffortJointInterface</hardwareInterface>
      <mechanicalReduction>1</mechanicalReduction>
    </actuator>
  </transmission>
  <!--link 6-->
  <link name="AR5-5_07R-W4C4A2_link6">
    <visual>
      <geometry>
        <mesh filename="package://AR5-5_07R-W4C4A2_description/meshes/AR5-5_07R-W4C4A2_link6.stl" scale="0.001 0.001 0.001"/>
      </geometry>
      <origin rpy="0 0 0" xyz="0 0 0"/>
      <material name="white"/>
    </visual>
    <inertial>
    <mass value="0.828457" />
    <inertia ixx="7.226967e-04" ixy="1.498014e-06" ixz="-1.197575e-06" iyy="8.756205e-04" iyz="5.661506e-07" izz="9.262879e-04" />
    <origin rpy="0 0 0" xyz="0.005806 -0.000689 0.000062" />
    </inertial>
    <collision>
      <geometry>
        <mesh filename="package://AR5-5_07R-W4C4A2_description/meshes/AR5-5_07R-W4C4A2_link6.stl" scale="0.001 0.001 0.001"/>
      </geometry>
      <origin rpy="0 0 0" xyz="0 0 0"/>
    </collision>
  </link>
  <joint name="AR5-5_07R-W4C4A2_joint_7" type="revolute">
    <parent link="AR5-5_07R-W4C4A2_link6"/>
    <child link="AR5-5_07R-W4C4A2_link7"/>
    <limit effort="19" lower="-1.0472" upper="1.0472" velocity="4.1887902047863905"/>
    <axis xyz="1 0 0"/>
    <origin rpy="0.0 0.0 0" xyz="0.0 0.0 0.0"/>
    <dynamics damping="3.8004009647e-02" friction="1.0773644772e-01"/>
  </joint>
  <transmission name="tran7">
    <type>transmission_interface/SimpleTransmission</type>
    <joint name="xmate_joint_7">
      <hardwareInterface>EffortJointInterface</hardwareInterface>
    </joint>
    <actuator name="motor7">
      <hardwareInterface>EffortJointInterface</hardwareInterface>
      <mechanicalReduction>1</mechanicalReduction>
    </actuator>
  </transmission>
  <!--link 7-->
  <link name="AR5-5_07R-W4C4A2_link7">
    <visual>
      <geometry>
        <mesh filename="package://AR5-5_07R-W4C4A2_description/meshes/AR5-5_07R-W4C4A2_link7.stl" scale="0.001 0.001 0.001"/>
      </geometry>
      <origin rpy="0 0 0" xyz="0.0 0.0 0.0"/>
      <material name="white"/>
    </visual>
    <inertial>
    <mass value="0.230457" />
    <inertia ixx="7.997047e-05" ixy="1.876834e-07" ixz="1.623466e-05" iyy="3.516215e-04" iyz="1.229339e-06" izz="4.598208e-04" />
    <origin rpy="0 0 0" xyz="-0.003913 0.000045 0.079210" />
    </inertial>
    <collision>
      <geometry>
        <mesh filename="package://AR5-5_07R-W4C4A2_description/meshes/AR5-5_07R-W4C4A2_link7.stl" scale="0.001 0.001 0.001"/>
      </geometry>
      <origin rpy="0 0 0" xyz="0.0 0.0 0.0"/>
    </collision>
  </link>
  <link name="AR5-5_07R-W4C4A2_tcp">
    <inertial>
      <mass value="0.0"/>
      <inertia ixx="1e-6" ixy="0" ixz="0" iyy="1e-6" iyz="0" izz="1e-6"/>
    </inertial>
  </link>
  <joint name="AR5-5_07R-W4C4A2_tcp_joint" type="fixed">
    <parent link="AR5-5_07R-W4C4A2_link7"/>
    <child link="AR5-5_07R-W4C4A2_tcp"/>
    <origin rpy="0 0 0" xyz="0.0 0.0 0.0968883"/>
  </joint>
</robot>
