<?xml version='1.0' encoding='UTF-8'?>
<robot xmlns:xacro="http://www.ros.org/wiki/xacro" name="AR5-5_07R-W4C4A2">
  <!-- Constants for robot dimensions -->
  <material name="black">
    <color rgba="0.0 0.0 0.0 1.0"/>
  </material>
  <material name="blue">
    <color rgba="0.0 0.0 0.8 1.0"/>
  </material>
  <material name="green">
    <color rgba="0.0 0.8 0.0 1.0"/>
  </material>
  <material name="grey">
    <color rgba="0.2 0.2 0.2 1.0"/>
  </material>
  <material name="orange">
    <color rgba="1.0 0.423529411765 0.0392156862745 1.0"/>
  </material>
  <material name="brown">
    <color rgba="0.870588235294 0.811764705882 0.764705882353 1.0"/>
  </material>
  <material name="red">
    <color rgba="0.8 0.0 0.0 1.0"/>
  </material>
  <material name="white">
    <color rgba="1.0 1.0 1.0 1.0"/>
  </material>
  <material name="Beige">
    <color rgba="1.0 0.784 0.5765 1.0"/>
  </material>
  <!-- Used for fixing robot to Gazebo 'base_link' -->
  <link name="world"/>
  <joint name="fixed" type="fixed">
    <parent link="world"/>
    <child link="AR5-5_07R-W4C4A2_base"/>
  </joint>
  <!--base-->
  <link name="AR5-5_07R-W4C4A2_base">
    <visual>
      <geometry>
        <mesh filename="package://AR5-5_07R-W4C4A2_description/meshes/AR5-5_07R-W4C4A2_base.stl" scale="0.001 0.001 0.001"/>
      </geometry>
      <origin rpy="0 0 0" xyz="0.0 0.0 0.0"/>
      <material name="white"/>
    </visual>
    <collision>
      <geometry>
        <mesh filename="package://AR5-5_07R-W4C4A2_description/meshes/AR5-5_07R-W4C4A2_base.stl" scale="0.001 0.001 0.001"/>
      </geometry>
      <origin rpy="0 0 0" xyz="0.0 0.0 0.0"/>
    </collision>
  </link>
  <joint name="AR5-5_07R-W4C4A2_joint_1" type="revolute">
    <parent link="AR5-5_07R-W4C4A2_base"/>
    <child link="AR5-5_07R-W4C4A2_link1"/>
    <limit effort="108" lower="-3.1067" upper="3.1067" velocity="3.0543261909900763"/>
    <axis xyz="0 0 1"/>
    <origin rpy="0 0 0" xyz="0.0 0.0 0.0"/>
    <dynamics damping="0.0000000000e+00" friction="0.0000000000e+00"/>
  </joint>
  <transmission name="tran1">
    <type>transmission_interface/SimpleTransmission</type>
    <joint name="AR5-5_07R-W4C4A2_joint_8">
      <hardwareInterface>EffortJointInterface</hardwareInterface>
    </joint>
    <actuator name="motor1">
      <hardwareInterface>EffortJointInterface</hardwareInterface>
      <mechanicalReduction>1</mechanicalReduction>
    </actuator>
  </transmission>
  <!--link 1-->
  <link name="AR5-5_07R-W4C4A2_link1">
    <visual>
      <geometry>
        <mesh filename="package://AR5-5_07R-W4C4A2_description/meshes/AR5-5_07R-W4C4A2_link1.stl" scale="0.001 0.001 0.001"/>
      </geometry>
      <origin rpy="0 0 0" xyz="0 0 0"/>
      <material name="white"/>
    </visual>
    <inertial>
    <mass value="2.683000" />
    <inertia ixx="4.934934e-03" ixy="1.409712e-06" ixz="2.984999e-05" iyy="4.523427e-03" iyz="-7.422830e-04" izz="4.327291e-03" />
    <origin rpy="0 0 0" xyz="0.000070 -0.001027 0.167909" />
    </inertial>
    <collision>
      <geometry>
        <mesh filename="package://AR5-5_07R-W4C4A2_description/meshes/AR5-5_07R-W4C4A2_link1.stl" scale="0.001 0.001 0.001"/>
      </geometry>
      <origin rpy="0 0 0" xyz="0 0 0"/>
    </collision>
  </link>
  <joint name="AR5-5_07R-W4C4A2_joint_2" type="revolute">
    <parent link="AR5-5_07R-W4C4A2_link1"/>
    <child link="AR5-5_07R-W4C4A2_link2"/>
    <limit effort="108" lower="-2.0944" upper="2.0944" velocity="3.0543261909900763"/>
    <axis xyz="0 1 0"/>
    <origin rpy="0 0 0" xyz="0.0 0.0 0.174522"/>
    <dynamics damping="0.0000000000e+00" friction="0.0000000000e+00"/>
  </joint>
  <transmission name="tran2">
    <type>transmission_interface/SimpleTransmission</type>
    <joint name="xmate_joint_2">
      <hardwareInterface>EffortJointInterface</hardwareInterface>
    </joint>
    <actuator name="motor2">
      <hardwareInterface>EffortJointInterface</hardwareInterface>
      <mechanicalReduction>1</mechanicalReduction>
    </actuator>
  </transmission>
  <!--link 2-->
  <link name="AR5-5_07R-W4C4A2_link2">
    <visual>
      <geometry>
        <mesh filename="package://AR5-5_07R-W4C4A2_description/meshes/AR5-5_07R-W4C4A2_link2.stl" scale="0.001 0.001 0.001"/>
      </geometry>
      <origin rpy="0 0 0" xyz="0 0 0.0"/>
      <material name="white"/>
    </visual>
    <inertial>
    <mass value="2.300000" />
    <inertia ixx="1.138177e-02" ixy="2.541072e-06" ixz="1.568310e-05" iyy="9.777298e-03" iyz="-1.279291e-03" izz="4.371101e-03" />
    <origin rpy="0 0 0" xyz="0.000084 0.001158 0.103315" />
    </inertial>
    <collision>
      <geometry>
        <mesh filename="package://AR5-5_07R-W4C4A2_description/meshes/AR5-5_07R-W4C4A2_link2.stl" scale="0.001 0.001 0.001"/>
      </geometry>
      <origin rpy="0 0 0" xyz="0 0 0.0"/>
    </collision>
  </link>
  <joint name="AR5-5_07R-W4C4A2_joint_3" type="revolute">
    <parent link="AR5-5_07R-W4C4A2_link2"/>
    <child link="AR5-5_07R-W4C4A2_link3"/>
    <limit effort="66" lower="-3.1067" upper="3.1067" velocity="4.71238898038469"/>
    <axis xyz="0 0 1"/>
    <origin rpy="0 0 0" xyz="0.0 0.0 0.314726"/>
    <dynamics damping="0.0000000000e+00" friction="0.0000000000e+00"/>
  </joint>
  <transmission name="tran3">
    <type>transmission_interface/SimpleTransmission</type>
    <joint name="xmate_joint_3">
      <hardwareInterface>EffortJointInterface</hardwareInterface>
    </joint>
    <actuator name="motor3">
      <hardwareInterface>EffortJointInterface</hardwareInterface>
      <mechanicalReduction>1</mechanicalReduction>
    </actuator>
  </transmission>
  <!--link 3-->
  <link name="AR5-5_07R-W4C4A2_link3">
    <visual>
      <geometry>
        <mesh filename="package://AR5-5_07R-W4C4A2_description/meshes/AR5-5_07R-W4C4A2_link3.stl" scale="0.001 0.001 0.001"/>
      </geometry>
      <origin rpy="0 0 0" xyz="0 0 0"/>
      <material name="white"/>
    </visual>
    <inertial>
    <mass value="1.862461" />
    <inertia ixx="5.264487e-03" ixy="-1.609664e-05" ixz="6.563263e-04" iyy="4.851501e-03" iyz="1.505714e-05" izz="2.745052e-03" />
    <origin rpy="0 0 0" xyz="-0.002855 -0.000987 -0.015343" />
    </inertial>
    <collision>
      <geometry>
        <mesh filename="package://AR5-5_07R-W4C4A2_description/meshes/AR5-5_07R-W4C4A2_link3.stl" scale="0.001 0.001 0.001"/>
      </geometry>
      <origin rpy="0 0 0" xyz="0 0 0"/>
    </collision>
  </link>
  <joint name="AR5-5_07R-W4C4A2_joint_4" type="revolute">
    <parent link="AR5-5_07R-W4C4A2_link3"/>
    <child link="AR5-5_07R-W4C4A2_link4"/>
    <limit effort="66" lower="-1.0472" upper="2.5307" velocity="5.235987755982989"/>
    <!--     lower="-1.0472" upper="1.0472" -->
    <axis xyz="0 1 0"/>
    <!--     <origin rpy="0 0 0" xyz=0.01 0.0 0.0/> -->
    <origin rpy="0 0 0" xyz="0.01 0.0 0.0"/>
    <dynamics damping="0.0000000000e+00" friction="0.0000000000e+00"/>
  </joint>
  <transmission name="tran4">
    <type>transmission_interface/SimpleTransmission</type>
    <joint name="xmate_joint_4">
      <hardwareInterface>EffortJointInterface</hardwareInterface>
    </joint>
    <actuator name="motor4">
      <hardwareInterface>EffortJointInterface</hardwareInterface>
      <mechanicalReduction>1</mechanicalReduction>
    </actuator>
  </transmission>
  <!--link 4-->
  <link name="AR5-5_07R-W4C4A2_link4">
    <visual>
      <geometry>
        <mesh filename="package://AR5-5_07R-W4C4A2_description/meshes/AR5-5_07R-W4C4A2_link4.stl" scale=".001 0.001 0.001"/>
      </geometry>
      <origin rpy="0 0 0" xyz="0.0 0.0 0.0"/>
      <material name="white"/>
    </visual>
    <inertial>
    <mass value="1.234410" />
    <inertia ixx="5.074483e-03" ixy="5.800187e-05" ixz="-4.929006e-04" iyy="4.129352e-03" iyz="-6.914765e-04" izz="1.782512e-03" />
    <origin rpy="0 0 0" xyz="-0.012548 0.001900 0.066674" />
    </inertial>
    <collision>
      <geometry>
        <mesh filename="package://AR5-5_07R-W4C4A2_description/meshes/AR5-5_07R-W4C4A2_link4.stl" scale="0.001 0.001 0.001"/>
      </geometry>
      <origin rpy="0 0 0" xyz="0.0 0.0 0.0"/>
    </collision>
  </link>
  <joint name="AR5-5_07R-W4C4A2_joint_5" type="revolute">
    <parent link="AR5-5_07R-W4C4A2_link4"/>
    <child link="AR5-5_07R-W4C4A2_link5"/>
    <limit effort="19" lower="-3.1067" upper="3.1067" velocity="4.1887902047863905"/>
    <axis xyz="0 0 1"/>
    <origin rpy="0 0 0" xyz="-0.01 0.0 0.272656"/>
    <dynamics damping="0.0000000000e+00" friction="0.0000000000e+00"/>
  </joint>
  <transmission name="tran5">
    <type>transmission_interface/SimpleTransmission</type>
    <joint name="xmate_joint_5">
      <hardwareInterface>EffortJointInterface</hardwareInterface>
    </joint>
    <actuator name="motor5">
      <hardwareInterface>EffortJointInterface</hardwareInterface>
      <mechanicalReduction>1</mechanicalReduction>
    </actuator>
  </transmission>
  <!--link 5-->
  <link name="AR5-5_07R-W4C4A2_link5">
    <visual>
      <geometry>
        <mesh filename="package://AR5-5_07R-W4C4A2_description/meshes/AR5-5_07R-W4C4A2_link5.stl" scale="0.001 0.001 0.001"/>
      </geometry>
      <origin rpy="0 0 0" xyz="0 0 0"/>
      <material name="white"/>
    </visual>
    <inertial>
    <mass value="1.327300" />
    <inertia ixx="1.976919e-03" ixy="-1.378879e-04" ixz="-3.287608e-03" iyy="2.703574e-04" iyz="2.000446e-04" izz="7.539224e-04" />
    <origin rpy="0 0 0" xyz="0.028601 -0.003310 -0.087906" />
    </inertial>
    <collision>
      <geometry>
        <mesh filename="package://AR5-5_07R-W4C4A2_description/meshes/AR5-5_07R-W4C4A2_link5.stl" scale="0.001 0.001 0.001"/>
      </geometry>
      <origin rpy="0 0 0" xyz="0 0 0"/>
    </collision>
  </link>
  <joint name="AR5-5_07R-W4C4A2_joint_6" type="revolute">
    <parent link="AR5-5_07R-W4C4A2_link5"/>
    <child link="AR5-5_07R-W4C4A2_link6"/>
    <limit effort="19" lower="-1.0472" upper="1.0472" velocity="4.1887902047863905"/>
    <axis xyz="0 1 0"/>
    <origin rpy="0.0 0.0 0" xyz="0.0 0.0 0.0"/>
    <dynamics damping="0.0000000000e+00" friction="0.0000000000e+00"/>
  </joint>
  <transmission name="tran6">
    <type>transmission_interface/SimpleTransmission</type>
    <joint name="xmate_joint_6">
      <hardwareInterface>EffortJointInterface</hardwareInterface>
    </joint>
    <actuator name="motor6">
      <hardwareInterface>EffortJointInterface</hardwareInterface>
      <mechanicalReduction>1</mechanicalReduction>
    </actuator>
  </transmission>
  <!--link 6-->
  <link name="AR5-5_07R-W4C4A2_link6">
    <visual>
      <geometry>
        <mesh filename="package://AR5-5_07R-W4C4A2_description/meshes/AR5-5_07R-W4C4A2_link6.stl" scale="0.001 0.001 0.001"/>
      </geometry>
      <origin rpy="0 0 0" xyz="0 0 0"/>
      <material name="white"/>
    </visual>
    <inertial>
    <mass value="0.929300" />
    <inertia ixx="7.127075e-04" ixy="-1.040997e-05" ixz="2.487290e-06" iyy="8.790445e-04" iyz="-1.941203e-06" izz="9.210465e-04" />
    <origin rpy="0 0 0" xyz="0.005065 -0.003234 0.000846" />
    </inertial>
    <collision>
      <geometry>
        <mesh filename="package://AR5-5_07R-W4C4A2_description/meshes/AR5-5_07R-W4C4A2_link6.stl" scale="0.001 0.001 0.001"/>
      </geometry>
      <origin rpy="0 0 0" xyz="0 0 0"/>
    </collision>
  </link>
  <joint name="AR5-5_07R-W4C4A2_joint_7" type="revolute">
    <parent link="AR5-5_07R-W4C4A2_link6"/>
    <child link="AR5-5_07R-W4C4A2_link7"/>
    <limit effort="19" lower="-1.0472" upper="1.0472" velocity="4.1887902047863905"/>
    <axis xyz="1 0 0"/>
    <origin rpy="0.0 0.0 0" xyz="0.0 0.0 0.0"/>
    <dynamics damping="0.0000000000e+00" friction="0.0000000000e+00"/>
  </joint>
  <transmission name="tran7">
    <type>transmission_interface/SimpleTransmission</type>
    <joint name="xmate_joint_7">
      <hardwareInterface>EffortJointInterface</hardwareInterface>
    </joint>
    <actuator name="motor7">
      <hardwareInterface>EffortJointInterface</hardwareInterface>
      <mechanicalReduction>1</mechanicalReduction>
    </actuator>
  </transmission>
  <!--link 7-->
  <link name="AR5-5_07R-W4C4A2_link7">
    <visual>
      <geometry>
        <mesh filename="package://AR5-5_07R-W4C4A2_description/meshes/AR5-5_07R-W4C4A2_link7.stl" scale="0.001 0.001 0.001"/>
      </geometry>
      <origin rpy="0 0 0" xyz="0.0 0.0 0.0"/>
      <material name="white"/>
    </visual>
    <inertial>
    <mass value="0.331300" />
    <inertia ixx="6.522314e-04" ixy="-2.300939e-06" ixz="3.612313e-05" iyy="9.264614e-04" iyz="4.318213e-05" izz="4.582034e-04" />
    <origin rpy="0 0 0" xyz="-0.003033 0.002517 0.051291" />
    </inertial>
    <collision>
      <geometry>
        <mesh filename="package://AR5-5_07R-W4C4A2_description/meshes/AR5-5_07R-W4C4A2_link7.stl" scale="0.001 0.001 0.001"/>
      </geometry>
      <origin rpy="0 0 0" xyz="0.0 0.0 0.0"/>
    </collision>
  </link>
  <link name="AR5-5_07R-W4C4A2_tcp">
    <inertial>
      <mass value="0.0"/>
      <inertia ixx="1e-6" ixy="0" ixz="0" iyy="1e-6" iyz="0" izz="1e-6"/>
    </inertial>
  </link>
  <joint name="AR5-5_07R-W4C4A2_tcp_joint" type="fixed">
    <parent link="AR5-5_07R-W4C4A2_link7"/>
    <child link="AR5-5_07R-W4C4A2_tcp"/>
    <origin rpy="0 0 0" xyz="0.0 0.0 0.0968883"/>
  </joint>
</robot>
