<mujoco model="AR5-5_07R-W4C4A2">
  <compiler angle="radian"/>

  <asset>
    <mesh name="AR5-5_07R-W4C4A2_base" content_type="model/stl" file="AR5-5_07R-W4C4A2_base.stl" scale="0.001 0.001 0.001"/>
    <mesh name="AR5-5_07R-W4C4A2_link1" content_type="model/stl" file="AR5-5_07R-W4C4A2_link1.stl" scale="0.001 0.001 0.001"/>
    <mesh name="AR5-5_07R-W4C4A2_link2" content_type="model/stl" file="AR5-5_07R-W4C4A2_link2.stl" scale="0.001 0.001 0.001"/>
    <mesh name="AR5-5_07R-W4C4A2_link3" content_type="model/stl" file="AR5-5_07R-W4C4A2_link3.stl" scale="0.001 0.001 0.001"/>
    <mesh name="AR5-5_07R-W4C4A2_link4" content_type="model/stl" file="AR5-5_07R-W4C4A2_link4.stl" scale="0.001 0.001 0.001"/>
    <mesh name="AR5-5_07R-W4C4A2_link5" content_type="model/stl" file="AR5-5_07R-W4C4A2_link5.stl" scale="0.001 0.001 0.001"/>
    <mesh name="AR5-5_07R-W4C4A2_link6" content_type="model/stl" file="AR5-5_07R-W4C4A2_link6.stl" scale="0.001 0.001 0.001"/>
    <mesh name="AR5-5_07R-W4C4A2_link7" content_type="model/stl" file="AR5-5_07R-W4C4A2_link7.stl" scale="0.001 0.001 0.001"/>
  </asset>

  <worldbody>
    <geom type="mesh" rgba="1 1 1 1" mesh="AR5-5_07R-W4C4A2_base"/>
    <body name="AR5-5_07R-W4C4A2_link1">
      <inertial pos="-1e-06 0.000621 0.167909" quat="0.999997 0.000531118 0.00163028 0.00193396" mass="2.683" diaginertia="0.00493674 0.00452343 0.00432909"/>
      <joint name="AR5-5_07R-W4C4A2_joint_1" pos="0 0 0" axis="0 0 1" range="-3.1067 3.1067" actuatorfrcrange="-108 108"/>
      <geom type="mesh" rgba="1 1 1 1" mesh="AR5-5_07R-W4C4A2_link1"/>
      <body name="AR5-5_07R-W4C4A2_link2" pos="0 0 0.1745">
        <inertial pos="2e-05 0.003081 0.102986" quat="0.99742 -0.0717838 -3.70567e-06 0.000805645" mass="2.3" diaginertia="0.0115191 0.0100527 0.00423304"/>
        <joint name="AR5-5_07R-W4C4A2_joint_2" pos="0 0 0" axis="0 1 0" range="-2.0944 2.0944" actuatorfrcrange="-108 108"/>
        <geom type="mesh" rgba="1 1 1 1" mesh="AR5-5_07R-W4C4A2_link2"/>
        <body name="AR5-5_07R-W4C4A2_link3" pos="0 0 0.314">
          <inertial pos="0.007089 0.000655 -0.016514" quat="0.99748 -0.00638254 -0.0687629 -0.0162892" mass="1.862" diaginertia="0.00524608 0.00470371 0.00261784"/>
          <joint name="AR5-5_07R-W4C4A2_joint_3" pos="0 0 0" axis="0 0 1" range="-3.1067 3.1067" actuatorfrcrange="-66 66"/>
          <geom type="mesh" rgba="1 1 1 1" mesh="AR5-5_07R-W4C4A2_link3"/>
          <body name="AR5-5_07R-W4C4A2_link4" pos="0.01 0 0">
            <inertial pos="-0.007832 0.004209 0.073402" quat="0.984016 -0.159139 0.0445852 0.0663272" mass="1.234" diaginertia="0.00392013 0.00323212 0.00171433"/>
            <joint name="AR5-5_07R-W4C4A2_joint_4" pos="0 0 0" axis="0 1 0" range="-1.0472 2.5307" actuatorfrcrange="-66 66"/>
            <geom type="mesh" rgba="1 1 1 1" mesh="AR5-5_07R-W4C4A2_link4"/>
            <body name="AR5-5_07R-W4C4A2_link5" pos="-0.01 0 0.272">
              <inertial pos="0.000268 -0.001475 -0.084143" quat="0.999472 -0.0290985 -0.00973323 -0.010698" mass="1.328" diaginertia="0.0028436 0.00221131 0.00184958"/>
              <joint name="AR5-5_07R-W4C4A2_joint_5" pos="0 0 0" axis="0 0 1" range="-3.1067 3.1067" actuatorfrcrange="-19 19"/>
              <geom type="mesh" rgba="1 1 1 1" mesh="AR5-5_07R-W4C4A2_link5"/>
              <body name="AR5-5_07R-W4C4A2_link6">
                <inertial pos="0.005172 -0.000614 5.5e-05" quat="0.00812 0.704988 -0.000351095 0.709173" mass="0.93" diaginertia="0.000929393 0.000878686 0.00072271"/>
                <joint name="AR5-5_07R-W4C4A2_joint_6" pos="0 0 0" axis="0 1 0" range="-1.0472 1.0472" actuatorfrcrange="-19 19"/>
                <geom type="mesh" rgba="1 1 1 1" mesh="AR5-5_07R-W4C4A2_link6"/>
                <body name="AR5-5_07R-W4C4A2_link7">
                  <inertial pos="-0.002716 3.1e-05 0.054983" quat="0.690199 -0.155582 -0.157515 0.688918" mass="0.332" diaginertia="0.000793943 0.000539439 0.000441667"/>
                  <joint name="AR5-5_07R-W4C4A2_joint_7" pos="0 0 0" axis="1 0 0" range="-1.0472 1.0472" actuatorfrcrange="-19 19"/>
                  <geom type="mesh" rgba="1 1 1 1" mesh="AR5-5_07R-W4C4A2_link7"/>
                </body>
              </body>
            </body>
          </body>
        </body>
      </body>
    </body>
  </worldbody>
  <actuator>
    <!-- 关节1 基轴：改为扭矩 motor，ctrl 为关节力矩 (Nm) -->
    <motor name="AR5-5_07R-W4C4A2_joint_1_motor" joint="AR5-5_07R-W4C4A2_joint_1" gear="1" ctrlrange="-180 180" />
    <motor name="AR5-5_07R-W4C4A2_joint_2_motor" joint="AR5-5_07R-W4C4A2_joint_2" gear="1" ctrlrange="-180 180" />
    <motor name="AR5-5_07R-W4C4A2_joint_3_motor" joint="AR5-5_07R-W4C4A2_joint_3" gear="1" ctrlrange="-90 90" />
    <motor name="AR5-5_07R-W4C4A2_joint_4_motor" joint="AR5-5_07R-W4C4A2_joint_4" gear="1" ctrlrange="-90 90" />
    <!-- 关节5/6/7：保持原 forcerange 作为扭矩上下限 -->
    <motor name="AR5-5_07R-W4C4A2_joint_5_motor" joint="AR5-5_07R-W4C4A2_joint_5" gear="1" ctrlrange="-35 35" />
    <motor name="AR5-5_07R-W4C4A2_joint_6_motor" joint="AR5-5_07R-W4C4A2_joint_6" gear="1" ctrlrange="-35 35" />
    <motor name="AR5-5_07R-W4C4A2_joint_7_motor" joint="AR5-5_07R-W4C4A2_joint_7" gear="1" ctrlrange="-35 35" />
  </actuator>
  <keyframe>
    <key name="home" qpos="0 0 0 0 0 0 0" />
  </keyframe>
</mujoco>
