<?xml version='1.0' encoding='UTF-8'?>
<robot xmlns:xacro="http://www.ros.org/wiki/xacro" name="AR5-5_07R-W4C4A2">
  <!-- Constants for robot dimensions -->
  <material name="black">
    <color rgba="0.0 0.0 0.0 1.0"/>
  </material>
  <material name="blue">
    <color rgba="0.0 0.0 0.8 1.0"/>
  </material>
  <material name="green">
    <color rgba="0.0 0.8 0.0 1.0"/>
  </material>
  <material name="grey">
    <color rgba="0.2 0.2 0.2 1.0"/>
  </material>
  <material name="orange">
    <color rgba="1.0 0.423529411765 0.0392156862745 1.0"/>
  </material>
  <material name="brown">
    <color rgba="0.870588235294 0.811764705882 0.764705882353 1.0"/>
  </material>
  <material name="red">
    <color rgba="0.8 0.0 0.0 1.0"/>
  </material>
  <material name="white">
    <color rgba="1.0 1.0 1.0 1.0"/>
  </material>
  <material name="Beige">
    <color rgba="1.0 0.784 0.5765 1.0"/>
  </material>
  <!-- Used for fixing robot to Gazebo 'base_link' -->
  <link name="world"/>
  <joint name="fixed" type="fixed">
    <parent link="world"/>
    <child link="AR5-5_07R-W4C4A2_base"/>
  </joint>
  <!--base-->
  <link name="AR5-5_07R-W4C4A2_base">
    <visual>
      <geometry>
        <mesh filename="package://AR5-5_07R-W4C4A2_description/meshes/AR5-5_07R-W4C4A2_base.stl" scale="0.001 0.001 0.001"/>
      </geometry>
      <origin rpy="0 0 0" xyz="0.0 0.0 0.0"/>
      <material name="white"/>
    </visual>
    <collision>
      <geometry>
        <mesh filename="package://AR5-5_07R-W4C4A2_description/meshes/AR5-5_07R-W4C4A2_base.stl" scale="0.001 0.001 0.001"/>
      </geometry>
      <origin rpy="0 0 0" xyz="0.0 0.0 0.0"/>
    </collision>
  </link>
  <joint name="AR5-5_07R-W4C4A2_joint_1" type="revolute">
    <parent link="AR5-5_07R-W4C4A2_base"/>
    <child link="AR5-5_07R-W4C4A2_link1"/>
    <limit effort="108" lower="-3.1067" upper="3.1067" velocity="3.0543261909900763"/>
    <axis xyz="0 0 1"/>
    <origin rpy="0 0 0" xyz="0.0 0.0 0.0"/>
        <dynamics damping="0.065357" friction="0.323985" />
  </joint>
  <transmission name="tran1">
    <type>transmission_interface/SimpleTransmission</type>
    <joint name="AR5-5_07R-W4C4A2_joint_8">
      <hardwareInterface>EffortJointInterface</hardwareInterface>
    </joint>
    <actuator name="motor1">
      <hardwareInterface>EffortJointInterface</hardwareInterface>
      <mechanicalReduction>1</mechanicalReduction>
    </actuator>
  </transmission>
  <!--link 1-->
  <link name="AR5-5_07R-W4C4A2_link1">
    <visual>
      <geometry>
        <mesh filename="package://AR5-5_07R-W4C4A2_description/meshes/AR5-5_07R-W4C4A2_link1.stl" scale="0.001 0.001 0.001"/>
      </geometry>
      <origin rpy="0 0 0" xyz="0 0 0"/>
      <material name="white"/>
    </visual>
    <inertial>
      <mass value="2.683000" />
      <inertia ixx="4.9376267956e-03" ixy="1.3845687847e-05" ixz="-9.0705211476e-03" iyy="3.4361400206e-03" iyz="-3.8168579117e-04" izz="-1.0546275100e-01" />
      <origin rpy="0 0 0" xyz="-0.020131 -0.000227 0.167909" />
    </inertial>
    <collision>
      <geometry>
        <mesh filename="package://AR5-5_07R-W4C4A2_description/meshes/AR5-5_07R-W4C4A2_link1.stl" scale="0.001 0.001 0.001"/>
      </geometry>
      <origin rpy="0 0 0" xyz="0 0 0"/>
    </collision>
  </link>
  <joint name="AR5-5_07R-W4C4A2_joint_2" type="revolute">
    <parent link="AR5-5_07R-W4C4A2_link1"/>
    <child link="AR5-5_07R-W4C4A2_link2"/>
    <limit effort="108" lower="-2.0944" upper="2.0944" velocity="3.0543261909900763"/>
    <axis xyz="0 1 0"/>
    <origin rpy="0 0 0" xyz="0.0 0.0 0.174522"/>
        <dynamics damping="0.002218" friction="-0.333801" />
  </joint>
  <transmission name="tran2">
    <type>transmission_interface/SimpleTransmission</type>
    <joint name="xmate_joint_2">
      <hardwareInterface>EffortJointInterface</hardwareInterface>
    </joint>
    <actuator name="motor2">
      <hardwareInterface>EffortJointInterface</hardwareInterface>
      <mechanicalReduction>1</mechanicalReduction>
    </actuator>
  </transmission>
  <!--link 2-->
  <link name="AR5-5_07R-W4C4A2_link2">
    <visual>
      <geometry>
        <mesh filename="package://AR5-5_07R-W4C4A2_description/meshes/AR5-5_07R-W4C4A2_link2.stl" scale="0.001 0.001 0.001"/>
      </geometry>
      <origin rpy="0 0 0" xyz="0 0 0.0"/>
      <material name="white"/>
    </visual>
    <inertial>
      <mass value="2.300000" />
      <inertia ixx="-7.5618704297e-02" ixy="-1.6086104181e-02" ixz="-1.0180958485e-01" iyy="-2.1739298774e-01" iyz="-1.1961499155e-02" izz="-3.1896110605e-02" />
      <origin rpy="0 0 0" xyz="0.002310 0.002092 0.130361" />
    </inertial>
    <collision>
      <geometry>
        <mesh filename="package://AR5-5_07R-W4C4A2_description/meshes/AR5-5_07R-W4C4A2_link2.stl" scale="0.001 0.001 0.001"/>
      </geometry>
      <origin rpy="0 0 0" xyz="0 0 0.0"/>
    </collision>
  </link>
  <joint name="AR5-5_07R-W4C4A2_joint_3" type="revolute">
    <parent link="AR5-5_07R-W4C4A2_link2"/>
    <child link="AR5-5_07R-W4C4A2_link3"/>
    <limit effort="66" lower="-3.1067" upper="3.1067" velocity="4.71238898038469"/>
    <axis xyz="0 0 1"/>
    <origin rpy="0 0 0" xyz="0.0 0.0 0.314726"/>
        <dynamics damping="0.144342" friction="0.178867" />
  </joint>
  <transmission name="tran3">
    <type>transmission_interface/SimpleTransmission</type>
    <joint name="xmate_joint_3">
      <hardwareInterface>EffortJointInterface</hardwareInterface>
    </joint>
    <actuator name="motor3">
      <hardwareInterface>EffortJointInterface</hardwareInterface>
      <mechanicalReduction>1</mechanicalReduction>
    </actuator>
  </transmission>
  <!--link 3-->
  <link name="AR5-5_07R-W4C4A2_link3">
    <visual>
      <geometry>
        <mesh filename="package://AR5-5_07R-W4C4A2_description/meshes/AR5-5_07R-W4C4A2_link3.stl" scale="0.001 0.001 0.001"/>
      </geometry>
      <origin rpy="0 0 0" xyz="0 0 0"/>
      <material name="white"/>
    </visual>
    <inertial>
      <mass value="1.853578" />
      <inertia ixx="-9.8357064801e-02" ixy="2.9371378466e-02" ixz="1.2147336826e-01" iyy="-2.0203391567e-01" iyz="-3.3170119012e-03" izz="-3.8029066700e-02" />
      <origin rpy="0 0 0" xyz="0.039769 -0.000558 -0.079430" />
    </inertial>
    <collision>
      <geometry>
        <mesh filename="package://AR5-5_07R-W4C4A2_description/meshes/AR5-5_07R-W4C4A2_link3.stl" scale="0.001 0.001 0.001"/>
      </geometry>
      <origin rpy="0 0 0" xyz="0 0 0"/>
    </collision>
  </link>
  <joint name="AR5-5_07R-W4C4A2_joint_4" type="revolute">
    <parent link="AR5-5_07R-W4C4A2_link3"/>
    <child link="AR5-5_07R-W4C4A2_link4"/>
    <limit effort="66" lower="-1.0472" upper="2.5307" velocity="5.235987755982989"/>
    <!--     lower="-1.0472" upper="1.0472" -->
    <axis xyz="0 1 0"/>
    <!--     <origin rpy="0 0 0" xyz=0.01 0.0 0.0/> -->
    <origin rpy="0 0 0" xyz="0.01 0.0 0.0"/>
        <dynamics damping="0.001017" friction="0.201492" />
  </joint>
  <transmission name="tran4">
    <type>transmission_interface/SimpleTransmission</type>
    <joint name="xmate_joint_4">
      <hardwareInterface>EffortJointInterface</hardwareInterface>
    </joint>
    <actuator name="motor4">
      <hardwareInterface>EffortJointInterface</hardwareInterface>
      <mechanicalReduction>1</mechanicalReduction>
    </actuator>
  </transmission>
  <!--link 4-->
  <link name="AR5-5_07R-W4C4A2_link4">
    <visual>
      <geometry>
        <mesh filename="package://AR5-5_07R-W4C4A2_description/meshes/AR5-5_07R-W4C4A2_link4.stl" scale=".001 0.001 0.001"/>
      </geometry>
      <origin rpy="0 0 0" xyz="0.0 0.0 0.0"/>
      <material name="white"/>
    </visual>
    <inertial>
      <mass value="1.226160" />
      <inertia ixx="-5.5499057669e-02" ixy="6.1043368096e-03" ixz="-1.3675108051e-01" iyy="-1.0526555226e-01" iyz="3.7287139576e-03" izz="-7.3417203292e-02" />
      <origin rpy="0 0 0" xyz="-0.022696 0.002157 0.092958" />
    </inertial>
    <collision>
      <geometry>
        <mesh filename="package://AR5-5_07R-W4C4A2_description/meshes/AR5-5_07R-W4C4A2_link4.stl" scale="0.001 0.001 0.001"/>
      </geometry>
      <origin rpy="0 0 0" xyz="0.0 0.0 0.0"/>
    </collision>
  </link>
  <joint name="AR5-5_07R-W4C4A2_joint_5" type="revolute">
    <parent link="AR5-5_07R-W4C4A2_link4"/>
    <child link="AR5-5_07R-W4C4A2_link5"/>
    <limit effort="19" lower="-3.1067" upper="3.1067" velocity="4.1887902047863905"/>
    <axis xyz="0 0 1"/>
    <origin rpy="0 0 0" xyz="-0.01 0.0 0.272656"/>
        <dynamics damping="0.104162" friction="0.120249" />
  </joint>
  <transmission name="tran5">
    <type>transmission_interface/SimpleTransmission</type>
    <joint name="xmate_joint_5">
      <hardwareInterface>EffortJointInterface</hardwareInterface>
    </joint>
    <actuator name="motor5">
      <hardwareInterface>EffortJointInterface</hardwareInterface>
      <mechanicalReduction>1</mechanicalReduction>
    </actuator>
  </transmission>
  <!--link 5-->
  <link name="AR5-5_07R-W4C4A2_link5">
    <visual>
      <geometry>
        <mesh filename="package://AR5-5_07R-W4C4A2_description/meshes/AR5-5_07R-W4C4A2_link5.stl" scale="0.001 0.001 0.001"/>
      </geometry>
      <origin rpy="0 0 0" xyz="0 0 0"/>
      <material name="white"/>
    </visual>
    <inertial>
      <mass value="1.314494" />
      <inertia ixx="-8.2633064441e-02" ixy="-9.2250686057e-03" ixz="3.2545319272e-03" iyy="-1.0031045938e-01" iyz="5.1880718035e-05" izz="2.4352505371e-02" />
      <origin rpy="0 0 0" xyz="0.006212 -0.002510 -0.134319" />
    </inertial>
    <collision>
      <geometry>
        <mesh filename="package://AR5-5_07R-W4C4A2_description/meshes/AR5-5_07R-W4C4A2_link5.stl" scale="0.001 0.001 0.001"/>
      </geometry>
      <origin rpy="0 0 0" xyz="0 0 0"/>
    </collision>
  </link>
  <joint name="AR5-5_07R-W4C4A2_joint_6" type="revolute">
    <parent link="AR5-5_07R-W4C4A2_link5"/>
    <child link="AR5-5_07R-W4C4A2_link6"/>
    <limit effort="19" lower="-1.0472" upper="1.0472" velocity="4.1887902047863905"/>
    <axis xyz="0 1 0"/>
    <origin rpy="0.0 0.0 0" xyz="0.0 0.0 0.0"/>
        <dynamics damping="0.071730" friction="0.348274" />
  </joint>
  <transmission name="tran6">
    <type>transmission_interface/SimpleTransmission</type>
    <joint name="xmate_joint_6">
      <hardwareInterface>EffortJointInterface</hardwareInterface>
    </joint>
    <actuator name="motor6">
      <hardwareInterface>EffortJointInterface</hardwareInterface>
      <mechanicalReduction>1</mechanicalReduction>
    </actuator>
  </transmission>
  <!--link 6-->
  <link name="AR5-5_07R-W4C4A2_link6">
    <visual>
      <geometry>
        <mesh filename="package://AR5-5_07R-W4C4A2_description/meshes/AR5-5_07R-W4C4A2_link6.stl" scale="0.001 0.001 0.001"/>
      </geometry>
      <origin rpy="0 0 0" xyz="0 0 0"/>
      <material name="white"/>
    </visual>
    <inertial>
      <mass value="0.916494" />
      <inertia ixx="-3.2311228350e-02" ixy="3.0099180192e-04" ixz="-1.1094611257e-03" iyy="-3.4072670472e-04" iyz="-2.4545352750e-04" izz="-1.5919514857e-02" />
      <origin rpy="0 0 0" xyz="0.004638 -0.002085 0.037384" />
    </inertial>
    <collision>
      <geometry>
        <mesh filename="package://AR5-5_07R-W4C4A2_description/meshes/AR5-5_07R-W4C4A2_link6.stl" scale="0.001 0.001 0.001"/>
      </geometry>
      <origin rpy="0 0 0" xyz="0 0 0"/>
    </collision>
  </link>
  <joint name="AR5-5_07R-W4C4A2_joint_7" type="revolute">
    <parent link="AR5-5_07R-W4C4A2_link6"/>
    <child link="AR5-5_07R-W4C4A2_link7"/>
    <limit effort="19" lower="-1.0472" upper="1.0472" velocity="4.1887902047863905"/>
    <axis xyz="1 0 0"/>
    <origin rpy="0.0 0.0 0" xyz="0.0 0.0 0.0"/>
        <dynamics damping="0.081266" friction="0.088584" />
  </joint>
  <transmission name="tran7">
    <type>transmission_interface/SimpleTransmission</type>
    <joint name="xmate_joint_7">
      <hardwareInterface>EffortJointInterface</hardwareInterface>
    </joint>
    <actuator name="motor7">
      <hardwareInterface>EffortJointInterface</hardwareInterface>
      <mechanicalReduction>1</mechanicalReduction>
    </actuator>
  </transmission>
  <!--link 7-->
  <link name="AR5-5_07R-W4C4A2_link7">
    <visual>
      <geometry>
        <mesh filename="package://AR5-5_07R-W4C4A2_description/meshes/AR5-5_07R-W4C4A2_link7.stl" scale="0.001 0.001 0.001"/>
      </geometry>
      <origin rpy="0 0 0" xyz="0.0 0.0 0.0"/>
      <material name="white"/>
    </visual>
    <inertial>
      <mass value="0.318494" />
      <inertia ixx="-1.0434090665e-03" ixy="5.6728597575e-06" ixz="-8.1356826087e-04" iyy="-9.2350697916e-03" iyz="3.0978616454e-04" izz="-5.5509673509e-03" />
      <origin rpy="0 0 0" xyz="-0.004588 0.008245 0.026356" />
    </inertial>
    <collision>
      <geometry>
        <mesh filename="package://AR5-5_07R-W4C4A2_description/meshes/AR5-5_07R-W4C4A2_link7.stl" scale="0.001 0.001 0.001"/>
      </geometry>
      <origin rpy="0 0 0" xyz="0.0 0.0 0.0"/>
    </collision>
  </link>
  <link name="AR5-5_07R-W4C4A2_tcp">
    <inertial>
      <mass value="0.0"/>
      <inertia ixx="1e-6" ixy="0" ixz="0" iyy="1e-6" iyz="0" izz="1e-6"/>
    </inertial>
  </link>
  <joint name="AR5-5_07R-W4C4A2_tcp_joint" type="fixed">
    <parent link="AR5-5_07R-W4C4A2_link7"/>
    <child link="AR5-5_07R-W4C4A2_tcp"/>
    <origin rpy="0 0 0" xyz="0.0 0.0 0.0968883"/>
  </joint>
</robot>
